Workbook

Sheet Students
A1: student_id | B1: first_name | C1: last_name | D1: birth_date | E1: email | F1: phone | G1: group_id
A2: 1001 | B2: Aruzhan | C2: Nurlanova | D2: 38380 | E2: aruzhan.nurlanova@stud.univ.edu.kz | F2: +7 7010 318 36 16 | G2: 21
A3: 1002 | B3: Nursultan | C3: Serikov | D3: 38921 | E3: nursultan.serikov@stud.univ.edu.kz | F3: +7 7060 529 19 82 | G3: 22
A4: 1003 | B4: Dias | C4: Abdrakhmanov | D4: 38832 | E4: dias.abdrakhmanov@stud.univ.edu.kz | F4: +7 7044 444 21 49 | G4: 23
A5: 1004 | B5: Aisha | C5: Kenzhebayeva | D5: 38366 | E5: aisha.kenzhebayeva@stud.univ.edu.kz | F5: +7 7025 237 41 22 | G5: 24
A6: 1005 | B6: Yerkebulan | C6: Tokhtarov | D6: 38732 | E6: yerkebulan.tokhtarov@stud.univ.edu.kz | F6: +7 7072 281 97 81 | G6: 25
A7: 1006 | B7: Dilnaz | C7: Muratova | D7: 39311 | E7: dilnaz.muratova@stud.univ.edu.kz | F7: +7 7034 849 26 63 | G7: 26
A8: 1007 | B8: Alikhan | C8: Baimukhanov | D8: 38537 | E8: alikhan.baimukhanov@stud.univ.edu.kz | F8: +7 7060 530 37 10 | G8: 27
A9: 1008 | B9: Tomiris | C9: Yesenova | D9: 38635 | E9: tomiris.yesenova@stud.univ.edu.kz | F9: +7 7012 315 33 60 | G9: 28
A10: 1009 | B10: Sanzhar | C10: Zhaksylykov | D10: 39040 | E10: sanzhar.zhaksylykov@stud.univ.edu.kz | F10: +7 7022 143 28 37 | G10: 29
A11: 1010 | B11: Ayaulym | C11: Kairatova | D11: 38838 | E11: ayaulym.kairatova@stud.univ.edu.kz | F11: +7 7052 950 47 59 | G11: 30
A12: 1011 | B12: Bekzat | C12: Amanov | D12: 39116 | E12: bekzat.amanov@stud.univ.edu.kz | F12: +7 7036 696 91 41 | G12: 31
A13: 1012 | B13: Zarina | C13: Sultanova | D13: 39002 | E13: zarina.sultanova@stud.univ.edu.kz | F13: +7 7057 737 68 26 | G13: 32
... A31: 1030 | B31: Assem | C31: Yerzhanova | D31: 38386 | E31: assem.yerzhanova@stud.univ.edu.kz | F31: +7 7021 754 24 42 | G31: 35

Sheet Groups
A1: group_id | B1: group_name | C1: study_year | D1: department_id
A2: 21 | B2: IS-23 | C2: 4 | D2: 1
A3: 22 | B3: IS-24 | C3: 3 | D3: 1
A4: 23 | B4: IS-25 | C4: 2 | D4: 1
A5: 24 | B5: CE-23 | C5: 4 | D5: 2
A6: 25 | B6: CE-24 | C6: 3 | D6: 2
A7: 26 | B7: CE-25 | C7: 2 | D7: 2
A8: 27 | B8: MATH-24 | C8: 3 | D8: 3
A9: 28 | B9: ECON-23 | C9: 4 | D9: 4
A10: 29 | B10: ECON-25 | C10: 2 | D10: 4
A11: 30 | B11: PE-24 | C11: 3 | D11: 7
A12: 31 | B12: PE-25 | C12: 2 | D12: 7
A13: 32 | B13: ACC-24 | C13: 3 | D13: 11
... A16: 35 | B16: FL-24 | C16: 3 | D16: 5

Sheet Teachers
A1: teacher_id | B1: first_name | C1: last_name | D1: email | E1: phone | F1: department_id
A2: 201 | B2: Gaukhar | C2: Mustafina | D2: g.mustafina@univ.edu.kz | E2: +7 7067 986 81 69 | F2: 1
A3: 202 | B3: Nurlan | C3: Akhmetov | D3: n.akhmetov@univ.edu.kz | E3: +7 7067 620 85 34 | F3: 1
A4: 203 | B4: Saule | C4: Zhumabayeva | D4: s.zhumabayeva@univ.edu.kz | E4: +7 7033 923 75 70 | F4: 2
A5: 204 | B5: Yerlan | C5: Sadykov | D5: y.sadykov@univ.edu.kz | E5: +7 7033 196 67 48 | F5: 3
A6: 205 | B6: Gulnara | C6: Bekova | D6: g.bekova@univ.edu.kz | E6: +7 7028 192 78 98 | F6: 4
A7: 206 | B7: Marat | C7: Iskakov | D7: m.iskakov@univ.edu.kz | E7: +7 7015 709 60 67 | F7: 5
A8: 207 | B8: Dana | C8: Nurpeisova | D8: d.nurpeisova@univ.edu.kz | E8: +7 7030 738 11 77 | F8: 10
A9: 208 | B9: Bolat | C9: Tulegenov | D9: b.tulegenov@univ.edu.kz | E9: +7 7018 160 14 34 | F9: 9
A10: 209 | B10: Asel | C10: Kassymova | D10: a.kassymova@univ.edu.kz | E10: +7 7040 714 13 69 | F10: 1
A11: 210 | B11: Timur | C11: Ospanov | D11: t.ospanov@univ.edu.kz | E11: +7 7051 551 85 35 | F11: 2
A12: 211 | B12: Zhanar | C12: Abenova | D12: z.abenova@univ.edu.kz | E12: +7 7076 339 91 47 | F12: 3
A13: 212 | B13: Serik | C13: Mukhanov | D13: s.mukhanov@univ.edu.kz | E13: +7 7073 104 94 20 | F13: 6
... A18: 217 | B18: Kamila | C18: Saparova | D18: k.saparova@univ.edu.kz | E18: +7 7023 966 47 59 | F18: 12

Sheet Departments
A1: department_id | B1: department_name | C1: office_number | D1: phone
A2: 1 | B2: Information Systems | C2: A-210 | D2: +7 7122 30-11-01
A3: 2 | B3: Computer Engineering | C3: A-215 | D3: +7 7122 30-11-02
A4: 3 | B4: Mathematics | C4: B-120 | D4: +7 7122 30-11-03
A5: 4 | B5: Economics | C5: C-301 | D5: +7 7122 30-11-04
A6: 5 | B6: Foreign Languages | C6: C-205 | D6: +7 7122 30-11-05
A7: 6 | B7: Physics | C7: B-305 | D7: +7 7122 30-11-06
A8: 7 | B8: Petroleum Engineering | C8: D-201 | D8: +7 7122 30-11-07
A9: 8 | B9: Chemistry | C9: D-204 | D9: +7 7122 30-11-08
A10: 9 | B10: History of Kazakhstan | C10: A-110 | D10: +7 7122 30-11-09
A11: 10 | B11: Philosophy | C11: A-112 | D11: +7 7122 30-11-10
A12: 11 | B12: Accounting and Audit | C12: C-310 | D12: +7 7122 30-11-11
A13: 12 | B13: Ecology | C13: D-306 | D13: +7 7122 30-11-12
... A16: 15 | B16: Pedagogy | C16: A-320 | D16: +7 7122 30-11-15

Sheet Courses
A1: course_id | B1: course_name | C1: credits | D1: department_id
A2: 301 | B2: Database Design and Data Management | C2: 5 | D2: 1
A3: 302 | B3: Algorithms and Data Structures | C3: 5 | D3: 2
A4: 303 | B4: Calculus I | C4: 5 | D4: 3
A5: 304 | B5: Microeconomics | C5: 5 | D5: 4
A6: 305 | B6: Professional English | C6: 3 | D6: 5
A7: 306 | B7: Philosophy | C7: 5 | D7: 10
A8: 307 | B8: Modern History of Kazakhstan | C8: 5 | D8: 9
A9: 308 | B9: Web Programming | C9: 5 | D9: 1
A10: 309 | B10: Computer Networks | C10: 5 | D10: 2
A11: 310 | B11: Linear Algebra | C11: 5 | D11: 3
A12: 311 | B12: General Physics | C12: 5 | D12: 6
A13: 312 | B13: Drilling Technology | C13: 6 | D13: 7
... A17: 316 | B17: Environmental Monitoring | C17: 4 | D17: 12

Sheet Classrooms
A1: classroom_id | B1: building | C1: room_number | D1: capacity
A2: 401 | B2: Main Building | C2: A-101 | D2: 120
A3: 402 | B3: Main Building | C3: A-102 | D3: 60
A4: 403 | B4: Main Building | C4: A-205 | D4: 30
A5: 404 | B5: Main Building | C5: A-207 | D5: 30
A6: 405 | B6: Building B | C6: B-110 | D6: 25
A7: 406 | B7: Building B | C7: B-112 | D7: 25
A8: 407 | B8: Building B | C8: B-214 | D8: 25
A9: 408 | B9: Building B | C9: B-301 | D9: 40
A10: 409 | B10: Building C | C10: C-104 | D10: 80
A11: 410 | B11: Building C | C11: C-210 | D11: 30
A12: 411 | B12: Building C | C12: C-212 | D12: 30
A13: 412 | B13: Building D | C13: D-101 | D13: 50
... A16: 415 | B16: Sports Complex | C16: SC-01 | D16: 200

Sheet Schedule
A1: schedule_id | B1: course_id | C1: teacher_id | D1: group_id | E1: classroom_id | F1: class_date | G1: start_time | H1: end_time
A2: 501 | B2: 308 | C2: 209 | D2: 21 | E2: 407 | F2: 46309 | G2: 0.35416667 | H2: 0.40972222
A3: 502 | B3: 301 | C3: 201 | D3: 22 | E3: 405 | F3: 46309 | G3: 0.41666667 | H3: 0.47222222
A4: 503 | B4: 302 | C4: 203 | D4: 23 | E4: 406 | F4: 46309 | G4: 0.47916667 | H4: 0.53472222
A5: 504 | B5: 309 | C5: 210 | D5: 24 | E5: 407 | F5: 46309 | G5: 0.58333333 | H5: 0.63888889
A6: 505 | B6: 302 | C6: 203 | D6: 25 | E6: 406 | F6: 46309 | G6: 0.64583333 | H6: 0.70138889
A7: 506 | B7: 310 | C7: 211 | D7: 26 | E7: 411 | F7: 46309 | G7: 0.35416667 | H7: 0.40972222
A8: 507 | B8: 310 | C8: 211 | D8: 27 | E8: 402 | F8: 46309 | G8: 0.41666667 | H8: 0.47222222
A9: 508 | B9: 313 | C9: 214 | D9: 28 | E9: 409 | F9: 46309 | G9: 0.47916667 | H9: 0.53472222
A10: 509 | B10: 304 | C10: 205 | D10: 29 | E10: 412 | F10: 46309 | G10: 0.58333333 | H10: 0.63888889
A11: 510 | B11: 312 | C11: 213 | D11: 30 | E11: 414 | F11: 46309 | G11: 0.64583333 | H11: 0.70138889
A12: 511 | B12: 311 | C12: 212 | D12: 31 | E12: 408 | F12: 46309 | G12: 0.35416667 | H12: 0.40972222
A13: 512 | B13: 313 | C13: 214 | D13: 32 | E13: 411 | F13: 46309 | G13: 0.41666667 | H13: 0.47222222
... A31: 530 | B31: 305 | C31: 206 | D31: 35 | E31: 410 | F31: 46310 | G31: 0.35416667 | H31: 0.40972222

Sheet Enrollments
A1: enrollment_id | B1: student_id | C1: course_id | D1: semester | E1: academic_year | F1: status
A2: 601 | B2: 1001 | C2: 301 | D2: 6 | E2: 2025-2026 | F2: Completed
A3: 602 | B3: 1001 | C3: 302 | D3: 6 | E3: 2025-2026 | F3: Completed
A4: 603 | B4: 1001 | C4: 308 | D4: 7 | E4: 2026-2027 | F4: Active
A5: 604 | B5: 1002 | C5: 302 | D5: 4 | E5: 2025-2026 | F5: Completed
A6: 605 | B6: 1002 | C6: 310 | D6: 4 | E6: 2025-2026 | F6: Completed
A7: 606 | B7: 1002 | C7: 301 | D7: 5 | E7: 2026-2027 | F7: Active
A8: 607 | B8: 1003 | C8: 303 | D8: 2 | E8: 2025-2026 | F8: Completed
A9: 608 | B9: 1003 | C9: 305 | D9: 2 | E9: 2025-2026 | F9: Completed
A10: 609 | B10: 1003 | C10: 302 | D10: 3 | E10: 2026-2027 | F10: Active
A11: 610 | B11: 1004 | C11: 302 | D11: 6 | E11: 2025-2026 | F11: Completed
A12: 611 | B12: 1004 | C12: 305 | D12: 6 | E12: 2025-2026 | F12: Completed
A13: 612 | B13: 1004 | C13: 309 | D13: 7 | E13: 2026-2027 | F13: Active
... A91: 690 | B91: 1030 | C91: 305 | D91: 5 | E91: 2026-2027 | F91: Active

Sheet Grades
A1: grade_id | B1: enrollment_id | C1: teacher_id | D1: grade_value | E1: grade_date
A2: 701 | B2: 601 | C2: 201 | D2: 86 | E2: 46177
A3: 702 | B3: 602 | C3: 203 | D3: 97 | E3: 46178
A4: 703 | B4: 604 | C4: 203 | D4: 89 | E4: 46176
A5: 704 | B5: 605 | C5: 211 | D5: 93 | E5: 46174
A6: 705 | B6: 607 | C6: 204 | D6: 79 | E6: 46178
A7: 706 | B7: 608 | C7: 206 | D7: 90 | E7: 46180
A8: 707 | B8: 610 | C8: 203 | D8: 53 | E8: 46178
A9: 708 | B9: 611 | C9: 206 | D9: 91 | E9: 46181
A10: 709 | B10: 613 | C10: 204 | D10: 83 | E10: 46177
A11: 710 | B11: 614 | C11: 212 | D11: 99 | E11: 46175
A12: 711 | B12: 616 | C12: 204 | D12: 70 | E12: 46178
A13: 712 | B13: 617 | C13: 208 | D13: 91 | E13: 46182
... A76: 775 | B76: 645 | C76: 206 | D76: 88 | E76: 46301

Sheet Data Dictionary
A1: table | B1: column | C1: data_type | D1: key / constraint
A2: Students | B2: student_id | C2: Integer | D2: PK
A3: Students | B3: first_name | C3: Text
A4: Students | B4: last_name | C4: Text
A5: Students | B5: birth_date | C5: Date
A6: Students | B6: email | C6: Text | D6: Unique
A7: Students | B7: phone | C7: Text
A8: Students | B8: group_id | C8: Integer | D8: FK → Groups
A9: Groups | B9: group_id | C9: Integer | D9: PK
A10: Groups | B10: group_name | C10: Text
A11: Groups | B11: study_year | C11: Integer
A12: Groups | B12: department_id | C12: Integer | D12: FK → Departments
A13: Teachers | B13: teacher_id | C13: Integer | D13: PK
A14: Teachers | B14: first_name | C14: Text
A15: Teachers | B15: last_name | C15: Text
A16: Teachers | B16: email | C16: Text | D16: Unique
A17: Teachers | B17: phone | C17: Text
A18: Teachers | B18: department_id | C18: Integer | D18: FK → Departments
A19: Departments | B19: department_id | C19: Integer | D19: PK
A20: Departments | B20: department_name | C20: Text
A21: Departments | B21: office_number | C21: Text
A22: Departments | B22: phone | C22: Text
A23: Courses | B23: course_id | C23: Integer | D23: PK
A24: Courses | B24: course_name | C24: Text
A25: Courses | B25: credits | C25: Integer | D25: > 0
A26: Courses | B26: department_id | C26: Integer | D26: FK → Departments
A27: Classrooms | B27: classroom_id | C27: Integer | D27: PK
A28: Classrooms | B28: building | C28: Text
A29: Classrooms | B29: room_number | C29: Text
A30: Classrooms | B30: capacity | C30: Integer | D30: > 0
A31: Schedule | B31: schedule_id | C31: Integer | D31: PK
A32: Schedule | B32: course_id | C32: Integer | D32: FK → Courses
A33: Schedule | B33: teacher_id | C33: Integer | D33: FK → Teachers
A34: Schedule | B34: group_id | C34: Integer | D34: FK → Groups
A35: Schedule | B35: classroom_id | C35: Integer | D35: FK → Classrooms
A36: Schedule | B36: class_date | C36: Date
A37: Schedule | B37: start_time | C37: Time | D37: < end_time
A38: Schedule | B38: end_time | C38: Time | D38: > start_time
A39: Enrollments | B39: enrollment_id | C39: Integer | D39: PK
A40: Enrollments | B40: student_id | C40: Integer | D40: FK → Students
...

Sheet P1_Sort_LastName
A1: Part 1.2 — Students sorted alphabetically by last_name (A→Z). Excel: Data → Sort → last_name, A to Z.
A3: student_id | B3: first_name | C3: last_name | D3: birth_date | E3: email | F3: phone | G3: group_id | H3: group_name
A4: 1003 | B4: Dias | C4: Abdrakhmanov | D4: 38832 | E4: dias.abdrakhmanov@stud.univ.edu.kz | F4: +7 7044 444 21 49 | G4: 23 | H4: =INDEX(Groups!$B:$B,MATCH(G4,Groups!$A:$A,0)) -> IS-25
A5: 1020 | B5: Diana | C5: Alieva | D5: 38355 | E5: diana.alieva@stud.univ.edu.kz | F5: +7 7044 521 67 41 | G5: 25 | H5: =INDEX(Groups!$B:$B,MATCH(G5,Groups!$A:$A,0)) -> CE-24
A6: 1011 | B6: Bekzat | C6: Amanov | D6: 39116 | E6: bekzat.amanov@stud.univ.edu.kz | F6: +7 7036 696 91 41 | G6: 31 | H6: =INDEX(Groups!$B:$B,MATCH(G6,Groups!$A:$A,0)) -> PE-25
A7: 1016 | B7: Moldir | C7: Askarova | D7: 38031 | E7: moldir.askarova@stud.univ.edu.kz | F7: +7 7016 206 23 14 | G7: 21 | H7: =INDEX(Groups!$B:$B,MATCH(G7,Groups!$A:$A,0)) -> IS-23
A8: 1007 | B8: Alikhan | C8: Baimukhanov | D8: 38537 | E8: alikhan.baimukhanov@stud.univ.edu.kz | F8: +7 7060 530 37 10 | G8: 27 | H8: =INDEX(Groups!$B:$B,MATCH(G8,Groups!$A:$A,0)) -> MATH-24
A9: 1013 | B9: Arman | C9: Bekov | D9: 38226 | E9: arman.bekov@stud.univ.edu.kz | F9: +7 7027 987 59 33 | G9: 33 | H9: =INDEX(Groups!$B:$B,MATCH(G9,Groups!$A:$A,0)) -> LAW-23
A10: 1023 | B10: Daniyar | C10: Berikov | D10: 38338 | E10: daniyar.berikov@stud.univ.edu.kz | F10: +7 7027 704 14 12 | G10: 28 | H10: =INDEX(Groups!$B:$B,MATCH(G10,Groups!$A:$A,0)) -> ECON-23
A11: 1017 | B11: Adil | C11: Dosmukhamedov | D11: 38480 | E11: adil.dosmukhamedov@stud.univ.edu.kz | F11: +7 7060 363 63 86 | G11: 22 | H11: =INDEX(Groups!$B:$B,MATCH(G11,Groups!$A:$A,0)) -> IS-24
A12: 1018 | B12: Akbota | C12: Ibrayeva | D12: 39219 | E12: akbota.ibrayeva@stud.univ.edu.kz | F12: +7 7032 837 18 26 | G12: 23 | H12: =INDEX(Groups!$B:$B,MATCH(G12,Groups!$A:$A,0)) -> IS-25
A13: 1010 | B13: Ayaulym | C13: Kairatova | D13: 38838 | E13: ayaulym.kairatova@stud.univ.edu.kz | F13: +7 7052 950 47 59 | G13: 30 | H13: =INDEX(Groups!$B:$B,MATCH(G13,Groups!$A:$A,0)) -> PE-24
A14: 1022 | B14: Aidana | C14: Kaliyeva | D14: 38760 | E14: aidana.kaliyeva@stud.univ.edu.kz | F14: +7 7027 561 52 94 | G14: 27 | H14: =INDEX(Groups!$B:$B,MATCH(G14,Groups!$A:$A,0)) -> MATH-24
A15: 1004 | B15: Aisha | C15: Kenzhebayeva | D15: 38366 | E15: aisha.kenzhebayeva@stud.univ.edu.kz | F15: +7 7025 237 41 22 | G15: 24 | H15: =INDEX(Groups!$B:$B,MATCH(G15,Groups!$A:$A,0)) -> CE-23
... A33: 1021 | B33: Miras | C33: Zhunusov | D33: 39088 | E33: miras.zhunusov@stud.univ.edu.kz | F33: +7 7046 477 77 83 | G33: 26 | H33: =INDEX(Groups!$B:$B,MATCH(G33,Groups!$A:$A,0)) -> CE-25

Sheet P1_Sort_Group
A1: Part 1.3 — Students sorted by group_id, then by last_name. Excel: Data → Sort → group_id, then add level last_name.
A3: student_id | B3: first_name | C3: last_name | D3: birth_date | E3: email | F3: phone | G3: group_id | H3: group_name
A4: 1016 | B4: Moldir | C4: Askarova | D4: 38031 | E4: moldir.askarova@stud.univ.edu.kz | F4: +7 7016 206 23 14 | G4: 21 | H4: =INDEX(Groups!$B:$B,MATCH(G4,Groups!$A:$A,0)) -> IS-23
A5: 1001 | B5: Aruzhan | C5: Nurlanova | D5: 38380 | E5: aruzhan.nurlanova@stud.univ.edu.kz | F5: +7 7010 318 36 16 | G5: 21 | H5: =INDEX(Groups!$B:$B,MATCH(G5,Groups!$A:$A,0)) -> IS-23
A6: 1017 | B6: Adil | C6: Dosmukhamedov | D6: 38480 | E6: adil.dosmukhamedov@stud.univ.edu.kz | F6: +7 7060 363 63 86 | G6: 22 | H6: =INDEX(Groups!$B:$B,MATCH(G6,Groups!$A:$A,0)) -> IS-24
A7: 1002 | B7: Nursultan | C7: Serikov | D7: 38921 | E7: nursultan.serikov@stud.univ.edu.kz | F7: +7 7060 529 19 82 | G7: 22 | H7: =INDEX(Groups!$B:$B,MATCH(G7,Groups!$A:$A,0)) -> IS-24
A8: 1003 | B8: Dias | C8: Abdrakhmanov | D8: 38832 | E8: dias.abdrakhmanov@stud.univ.edu.kz | F8: +7 7044 444 21 49 | G8: 23 | H8: =INDEX(Groups!$B:$B,MATCH(G8,Groups!$A:$A,0)) -> IS-25
A9: 1018 | B9: Akbota | C9: Ibrayeva | D9: 39219 | E9: akbota.ibrayeva@stud.univ.edu.kz | F9: +7 7032 837 18 26 | G9: 23 | H9: =INDEX(Groups!$B:$B,MATCH(G9,Groups!$A:$A,0)) -> IS-25
A10: 1004 | B10: Aisha | C10: Kenzhebayeva | D10: 38366 | E10: aisha.kenzhebayeva@stud.univ.edu.kz | F10: +7 7025 237 41 22 | G10: 24 | H10: =INDEX(Groups!$B:$B,MATCH(G10,Groups!$A:$A,0)) -> CE-23
A11: 1019 | B11: Nurasyl | C11: Shaikenov | D11: 38582 | E11: nurasyl.shaikenov@stud.univ.edu.kz | F11: +7 7019 386 37 36 | G11: 24 | H11: =INDEX(Groups!$B:$B,MATCH(G11,Groups!$A:$A,0)) -> CE-23
A12: 1020 | B12: Diana | C12: Alieva | D12: 38355 | E12: diana.alieva@stud.univ.edu.kz | F12: +7 7044 521 67 41 | G12: 25 | H12: =INDEX(Groups!$B:$B,MATCH(G12,Groups!$A:$A,0)) -> CE-24
A13: 1005 | B13: Yerkebulan | C13: Tokhtarov | D13: 38732 | E13: yerkebulan.tokhtarov@stud.univ.edu.kz | F13: +7 7072 281 97 81 | G13: 25 | H13: =INDEX(Groups!$B:$B,MATCH(G13,Groups!$A:$A,0)) -> CE-24
A14: 1006 | B14: Dilnaz | C14: Muratova | D14: 39311 | E14: dilnaz.muratova@stud.univ.edu.kz | F14: +7 7034 849 26 63 | G14: 26 | H14: =INDEX(Groups!$B:$B,MATCH(G14,Groups!$A:$A,0)) -> CE-25
A15: 1021 | B15: Miras | C15: Zhunusov | D15: 39088 | E15: miras.zhunusov@stud.univ.edu.kz | F15: +7 7046 477 77 83 | G15: 26 | H15: =INDEX(Groups!$B:$B,MATCH(G15,Groups!$A:$A,0)) -> CE-25
... A33: 1030 | B33: Assem | C33: Yerzhanova | D33: 38386 | E33: assem.yerzhanova@stud.univ.edu.kz | F33: +7 7021 754 24 42 | G33: 35 | H33: =INDEX(Groups!$B:$B,MATCH(G33,Groups!$A:$A,0)) -> FL-24

Sheet P1_Filter_Group
A1: Part 1.4 — Filter: only students of group 22 (IS-24). Excel: Data → Filter → group_id → tick 22. Hidden rows = other groups.
A3: student_id | B3: first_name | C3: last_name | D3: birth_date | E3: email | F3: phone | G3: group_id | H3: group_name
A4: 1001 | B4: Aruzhan | C4: Nurlanova | D4: 38380 | E4: aruzhan.nurlanova@stud.univ.edu.kz | F4: +7 7010 318 36 16 | G4: 21 | H4: =INDEX(Groups!$B:$B,MATCH(G4,Groups!$A:$A,0)) -> IS-23
A5: 1002 | B5: Nursultan | C5: Serikov | D5: 38921 | E5: nursultan.serikov@stud.univ.edu.kz | F5: +7 7060 529 19 82 | G5: 22 | H5: =INDEX(Groups!$B:$B,MATCH(G5,Groups!$A:$A,0)) -> IS-24
A6: 1003 | B6: Dias | C6: Abdrakhmanov | D6: 38832 | E6: dias.abdrakhmanov@stud.univ.edu.kz | F6: +7 7044 444 21 49 | G6: 23 | H6: =INDEX(Groups!$B:$B,MATCH(G6,Groups!$A:$A,0)) -> IS-25
A7: 1004 | B7: Aisha | C7: Kenzhebayeva | D7: 38366 | E7: aisha.kenzhebayeva@stud.univ.edu.kz | F7: +7 7025 237 41 22 | G7: 24 | H7: =INDEX(Groups!$B:$B,MATCH(G7,Groups!$A:$A,0)) -> CE-23
A8: 1005 | B8: Yerkebulan | C8: Tokhtarov | D8: 38732 | E8: yerkebulan.tokhtarov@stud.univ.edu.kz | F8: +7 7072 281 97 81 | G8: 25 | H8: =INDEX(Groups!$B:$B,MATCH(G8,Groups!$A:$A,0)) -> CE-24
A9: 1006 | B9: Dilnaz | C9: Muratova | D9: 39311 | E9: dilnaz.muratova@stud.univ.edu.kz | F9: +7 7034 849 26 63 | G9: 26 | H9: =INDEX(Groups!$B:$B,MATCH(G9,Groups!$A:$A,0)) -> CE-25
A10: 1007 | B10: Alikhan | C10: Baimukhanov | D10: 38537 | E10: alikhan.baimukhanov@stud.univ.edu.kz | F10: +7 7060 530 37 10 | G10: 27 | H10: =INDEX(Groups!$B:$B,MATCH(G10,Groups!$A:$A,0)) -> MATH-24
A11: 1008 | B11: Tomiris | C11: Yesenova | D11: 38635 | E11: tomiris.yesenova@stud.univ.edu.kz | F11: +7 7012 315 33 60 | G11: 28 | H11: =INDEX(Groups!$B:$B,MATCH(G11,Groups!$A:$A,0)) -> ECON-23
A12: 1009 | B12: Sanzhar | C12: Zhaksylykov | D12: 39040 | E12: sanzhar.zhaksylykov@stud.univ.edu.kz | F12: +7 7022 143 28 37 | G12: 29 | H12: =INDEX(Groups!$B:$B,MATCH(G12,Groups!$A:$A,0)) -> ECON-25
A13: 1010 | B13: Ayaulym | C13: Kairatova | D13: 38838 | E13: ayaulym.kairatova@stud.univ.edu.kz | F13: +7 7052 950 47 59 | G13: 30 | H13: =INDEX(Groups!$B:$B,MATCH(G13,Groups!$A:$A,0)) -> PE-24
A14: 1011 | B14: Bekzat | C14: Amanov | D14: 39116 | E14: bekzat.amanov@stud.univ.edu.kz | F14: +7 7036 696 91 41 | G14: 31 | H14: =INDEX(Groups!$B:$B,MATCH(G14,Groups!$A:$A,0)) -> PE-25
A15: 1012 | B15: Zarina | C15: Sultanova | D15: 39002 | E15: zarina.sultanova@stud.univ.edu.kz | F15: +7 7057 737 68 26 | G15: 32 | H15: =INDEX(Groups!$B:$B,MATCH(G15,Groups!$A:$A,0)) -> ACC-24
... A33: 1030 | B33: Assem | C33: Yerzhanova | D33: 38386 | E33: assem.yerzhanova@stud.univ.edu.kz | F33: +7 7021 754 24 42 | G33: 35 | H33: =INDEX(Groups!$B:$B,MATCH(G33,Groups!$A:$A,0)) -> FL-24

Sheet P1_Filter_2_Conditions
A1: Part 1.6 — Two conditions: group_id between 21 and 23 (Information Systems groups) AND birth_date on or after 2006-01-01. Excel: Number Filters on group_id + Date Filters on birth_date.
A3: student_id | B3: first_name | C3: last_name | D3: birth_date | E3: email | F3: phone | G3: group_id | H3: group_name
A4: 1001 | B4: Aruzhan | C4: Nurlanova | D4: 38380 | E4: aruzhan.nurlanova@stud.univ.edu.kz | F4: +7 7010 318 36 16 | G4: 21 | H4: =INDEX(Groups!$B:$B,MATCH(G4,Groups!$A:$A,0)) -> IS-23
A5: 1002 | B5: Nursultan | C5: Serikov | D5: 38921 | E5: nursultan.serikov@stud.univ.edu.kz | F5: +7 7060 529 19 82 | G5: 22 | H5: =INDEX(Groups!$B:$B,MATCH(G5,Groups!$A:$A,0)) -> IS-24
A6: 1003 | B6: Dias | C6: Abdrakhmanov | D6: 38832 | E6: dias.abdrakhmanov@stud.univ.edu.kz | F6: +7 7044 444 21 49 | G6: 23 | H6: =INDEX(Groups!$B:$B,MATCH(G6,Groups!$A:$A,0)) -> IS-25
A7: 1004 | B7: Aisha | C7: Kenzhebayeva | D7: 38366 | E7: aisha.kenzhebayeva@stud.univ.edu.kz | F7: +7 7025 237 41 22 | G7: 24 | H7: =INDEX(Groups!$B:$B,MATCH(G7,Groups!$A:$A,0)) -> CE-23
A8: 1005 | B8: Yerkebulan | C8: Tokhtarov | D8: 38732 | E8: yerkebulan.tokhtarov@stud.univ.edu.kz | F8: +7 7072 281 97 81 | G8: 25 | H8: =INDEX(Groups!$B:$B,MATCH(G8,Groups!$A:$A,0)) -> CE-24
A9: 1006 | B9: Dilnaz | C9: Muratova | D9: 39311 | E9: dilnaz.muratova@stud.univ.edu.kz | F9: +7 7034 849 26 63 | G9: 26 | H9: =INDEX(Groups!$B:$B,MATCH(G9,Groups!$A:$A,0)) -> CE-25
A10: 1007 | B10: Alikhan | C10: Baimukhanov | D10: 38537 | E10: alikhan.baimukhanov@stud.univ.edu.kz | F10: +7 7060 530 37 10 | G10: 27 | H10: =INDEX(Groups!$B:$B,MATCH(G10,Groups!$A:$A,0)) -> MATH-24
A11: 1008 | B11: Tomiris | C11: Yesenova | D11: 38635 | E11: tomiris.yesenova@stud.univ.edu.kz | F11: +7 7012 315 33 60 | G11: 28 | H11: =INDEX(Groups!$B:$B,MATCH(G11,Groups!$A:$A,0)) -> ECON-23
A12: 1009 | B12: Sanzhar | C12: Zhaksylykov | D12: 39040 | E12: sanzhar.zhaksylykov@stud.univ.edu.kz | F12: +7 7022 143 28 37 | G12: 29 | H12: =INDEX(Groups!$B:$B,MATCH(G12,Groups!$A:$A,0)) -> ECON-25
A13: 1010 | B13: Ayaulym | C13: Kairatova | D13: 38838 | E13: ayaulym.kairatova@stud.univ.edu.kz | F13: +7 7052 950 47 59 | G13: 30 | H13: =INDEX(Groups!$B:$B,MATCH(G13,Groups!$A:$A,0)) -> PE-24
A14: 1011 | B14: Bekzat | C14: Amanov | D14: 39116 | E14: bekzat.amanov@stud.univ.edu.kz | F14: +7 7036 696 91 41 | G14: 31 | H14: =INDEX(Groups!$B:$B,MATCH(G14,Groups!$A:$A,0)) -> PE-25
A15: 1012 | B15: Zarina | C15: Sultanova | D15: 39002 | E15: zarina.sultanova@stud.univ.edu.kz | F15: +7 7057 737 68 26 | G15: 32 | H15: =INDEX(Groups!$B:$B,MATCH(G15,Groups!$A:$A,0)) -> ACC-24
... A33: 1030 | B33: Assem | C33: Yerzhanova | D33: 38386 | E33: assem.yerzhanova@stud.univ.edu.kz | F33: +7 7021 754 24 42 | G33: 35 | H33: =INDEX(Groups!$B:$B,MATCH(G33,Groups!$A:$A,0)) -> FL-24

Sheet P1_Search
A1: Part 1.5 — Search for a student. Type a value in the yellow cell; the formulas find the record (Excel: Ctrl+F also works).
A3: Search by student_id: | B3: 1017
A4: student_id | B4: first_name | C4: last_name | D4: birth_date | E4: email | F4: phone | G4: group_id | H4: group_name
A5: =IFERROR(INDEX(Students!A:A,MATCH(B3,Students!A:A,0)),"not found") -> 1017 | B5: =IFERROR(INDEX(Students!B:B,MATCH(B3,Students!A:A,0)),"not found") -> Adil | C5: =IFERROR(INDEX(Students!C:C,MATCH(B3,Students!A:A,0)),"not found") -> Dosmukhamedov | D5: =IFERROR(INDEX(Students!D:D,MATCH(B3,Students!A:A,0)),"not found") -> 38480 | E5: =IFERROR(INDEX(Students!E:E,MATCH(B3,Students!A:A,0)),"not found") -> adil.dosmukhamedov@stud.univ.edu.kz | F5: =IFERROR(INDEX(Students!F:F,MATCH(B3,Students!A:A,0)),"not found") -> +7 7060 363 63 86 | G5: =IFERROR(INDEX(Students!G:G,MATCH(B3,Students!A:A,0)),"not found") -> 22 | H5: =IFERROR(INDEX(Groups!B:B,MATCH(G5,Groups!A:A,0)),"not found") -> IS-24
A9: Search by last_name: | B9: Omarova
A10: student_id | B10: first_name | C10: last_name | D10: birth_date | E10: email | F10: phone | G10: group_id | H10: group_name
A11: =IFERROR(INDEX(Students!A:A,MATCH(B9,Students!C:C,0)),"not found") -> 1014 | B11: =IFERROR(INDEX(Students!B:B,MATCH(B9,Students!C:C,0)),"not found") -> Inkar | C11: =IFERROR(INDEX(Students!C:C,MATCH(B9,Students!C:C,0)),"not found") -> Omarova | D11: =IFERROR(INDEX(Students!D:D,MATCH(B9,Students!C:C,0)),"not found") -> 38786 | E11: =IFERROR(INDEX(Students!E:E,MATCH(B9,Students!C:C,0)),"not found") -> inkar.omarova@stud.univ.edu.kz | F11: =IFERROR(INDEX(Students!F:F,MATCH(B9,Students!C:C,0)),"not found") -> +7 7039 937 88 41 | G11: =IFERROR(INDEX(Students!G:G,MATCH(B9,Students!C:C,0)),"not found") -> 34 | H11: =IFERROR(INDEX(Groups!B:B,MATCH(G11,Groups!A:A,0)),"not found") -> ECO-25
